<?xml version="1.0" ?>
<!-- =================================================================================== -->
<!-- |    This document was autogenerated by xacro from RoboFrencwfShinWalker.urdf.xacro | -->
<!-- |    EDITING THIS FILE BY HAND IS NOT RECOMMENDED                                 | -->
<!-- =================================================================================== -->
<robot name="openMutt">
  <!-- DAWG BODY -->
  <!-- DAWG BODY LAWNG -->
  <link name="base_link">
    <visual>
      <origin rpy="0 0 0" xyz="0 0 0"/>
      <axis xyz="0 0 0"/>
      <geometry>
        <box size="0.752 0.13 0.159"/>
      </geometry>
      <material name="c">
        <color rgba="0 0.9 0.9 1.0"/>
      </material>
    </visual>
    <collision>
      <origin rpy="0 0 0" xyz="0 0 0"/>
      <axis xyz="0 0 0"/>
      <geometry>
        <box size="0.752 0.13 0.159"/>
      </geometry>
    </collision>
  </link>
  <link name="faux_base_link">
    <inertial>
      <mass value="7"/>
      <inertia ixx=".0246" ixy="0.0" ixz="0.0" iyy=".345" iyz="0.0" izz="1.0"/>
      <origin rpy="0 0 0" xyz="0 0 0"/>
    </inertial>
  </link>
  <joint name="baseInertia" type="fixed">
    <parent link="base_link"/>
    <child link="faux_base_link"/>
    <origin rpy="0 0 0" xyz="0 0 0"/>
  </joint>
  <!-- DAWG BODY CHONK -->
  <link name="dogBodyCross">
    <inertial>
      <mass value="0.4"/>
      <inertia ixx="0.005067233333333333" ixy="0.0" ixz="0.0" iyy="0.003882833333333333" iyz="0.0" izz="0.007264666666666666"/>
    </inertial>
    <visual>
      <origin rpy="0 0 0" xyz="0 0 0"/>
      <axis xyz="0 0 0"/>
      <geometry>
        <box size="0.302 0.356 0.159"/>
      </geometry>
      <material name="c">
        <color rgba="0 0.9 0.9 1.0"/>
      </material>
    </visual>
    <collision>
      <origin rpy="0 0 0" xyz="0 0 0"/>
      <axis xyz="0 0 0"/>
      <geometry>
        <box size="0.302 0.356 0.159"/>
      </geometry>
    </collision>
  </link>
  <joint name="DawgBodyMaker" type="fixed">
    <parent link="base_link"/>
    <child link="dogBodyCross"/>
    <origin rpy="0 0 0" xyz="0 0 0"/>
  </joint>
  <!--prefix is the legnumber, xReflext is  a 1 or -1 and same with yReflect this just mkaes it swtich locations for all 4 quadrents but why are you reading this is you arent me, if youre this deep in you got yourself in trouble run before its too late... I mean seriously I am writing an essay here stop scrolling to the side just keep reading the code and ignore the comments or I guess this one, some are helpful this one was until you got too nosy-->
  <link name="frontRightHipBoxJointBearing">
    <inertial>
      <mass value="0.001"/>
      <inertia ixx="1.5e-07" ixy="0.0" ixz="0.0" iyy="2.0833333333333333e-07" iyz="0.0" izz="2.0833333333333333e-07"/>
    </inertial>
    <visual>
      <origin rpy="0 1.5809  0" xyz="0.151 -0.102 0"/>
      <axis xyz="0 0 0"/>
      <geometry>
        <cylinder length="0.04" radius="0.03"/>
      </geometry>
      <material name="Cyan1">
        <color rgba="0.3 0.15 0.9 1.0"/>
      </material>
    </visual>
    <collision>
      <origin rpy="0 1.5809  0" xyz="0.151 -0.102 0"/>
      <axis xyz="0 0 0"/>
      <geometry>
        <cylinder length="0.04" radius="0.03"/>
      </geometry>
    </collision>
  </link>
  <joint name="frontRightBodyHipBoxFixedBearing" type="fixed">
    <parent link="dogBodyCross"/>
    <child link="frontRightHipBoxJointBearing"/>
    <origin rpy="0 0 0" xyz="0 0 0"/>
  </joint>
  <!--X rotator allows for internal and external rotation-->
  <link name="frontRightHipRotateX">
    <inertial>
      <mass value="0.3"/>
      <inertia ixx="4.4999999999999996e-05" ixy="0.0" ixz="0.0" iyy="0.00028259999999999993" iyz="0.0" izz="0.00028259999999999993"/>
    </inertial>
    <visual>
      <origin rpy="0 1.5809 0" xyz="0.242 0 0"/>
      <axis xyz="0 0 0"/>
      <geometry>
        <cylinder length="0.102" radius="0.03"/>
      </geometry>
      <material name="Cyan1">
        <color rgba="0.3 0.15 0.9 1.0"/>
      </material>
    </visual>
    <collision>
      <origin rpy="0 1.5809 0" xyz="0.242 0 0"/>
      <axis xyz="0 0 0"/>
      <geometry>
        <cylinder length="0.102" radius="0.03"/>
      </geometry>
    </collision>
  </link>
  <!--Joint from This Bone to the Main Body-->
  <joint name="frontRightHipRotateXJoint" type="revolute">
    <parent link="frontRightHipBoxJointBearing"/>
    <child link="frontRightHipRotateX"/>
    <origin rpy="0 0 0" xyz="0 -0.102 0"/>
    <axis xyz="1 0 0"/>
    <limit effort="150" lower="-3.14159265359" upper="3.14159265359" velocity="1.5"/>
    <sensor name="frontRightHipRotateXJoint_torque" type="force_torque">
      <update_rate>30</update_rate>
    </sensor>
  </joint>
  <!--GazeboControls-->
  <transmission name="frontRighttran1">
    <type>transmission_interface/SimpleTransmission</type>
    <joint name="frontRightHipRotateXJoint">
      <hardwareInterface>hardware_interface/EffortJointInterface</hardwareInterface>
    </joint>
    <actuator name="frontRightmotor1">
      <hardwareInterface>hardware_interface/EffortJointInterface</hardwareInterface>
      <mechanicalReduction>1</mechanicalReduction>
    </actuator>
  </transmission>
  <!--Time to construct the hip box, makes me want to throw thousands into the march madness tournament, it will end differently this time I swear, massive value in the next Kentucky points over-->
  <!--Y block-->
  <link name="frontRightHipYBlock">
    <inertial>
      <mass value="0.001"/>
      <inertia ixx="1.5e-07" ixy="0.0" ixz="0.0" iyy="3.7499999999999996e-07" iyz="0.0" izz="3.7499999999999996e-07"/>
    </inertial>
    <visual>
      <origin rpy="1.5809 0 0" xyz="0.253 0 0"/>
      <axis xyz="0 0 0"/>
      <geometry>
        <cylinder length="0.06" radius="0.03"/>
      </geometry>
      <material name="Cyan1">
        <color rgba="0.3 0.15 0.9 1.0"/>
      </material>
    </visual>
    <collision>
      <origin rpy="0 0 0" xyz="0.253 0 0"/>
      <axis xyz="0 0 0"/>
      <geometry>
        <cylinder length="0.06" radius="0.03"/>
      </geometry>
    </collision>
  </link>
  <joint name="frontRightBodyHipBoxYAttach" type="fixed">
    <parent link="frontRightHipRotateX"/>
    <child link="frontRightHipYBlock"/>
    <origin rpy="0 0 0" xyz="0 0 0"/>
  </joint>
  <!--Y rotator allows for elevation and declanation rotation-->
  <link name="frontRightHipRotateY">
    <inertial>
      <mass value="0.5"/>
      <inertia ixx="7.5e-05" ixy="0.0" ixz="0.0" iyy="0.0012701666666666664" iyz="0.0" izz="0.0012701666666666664"/>
    </inertial>
    <visual>
      <origin rpy="1.5809 0 0" xyz="0 -0.03 0"/>
      <axis xyz="0 0 0"/>
      <geometry>
        <cylinder length="0.172" radius="0.03"/>
      </geometry>
      <material name="Cyan1">
        <color rgba="0.3 0.15 0.9 1.0"/>
      </material>
    </visual>
    <collision>
      <origin rpy="1.5809 0 0" xyz="0 -0.03 0"/>
      <axis xyz="0 0 0"/>
      <geometry>
        <cylinder length="0.102" radius="0.03"/>
      </geometry>
    </collision>
  </link>
  <joint name="frontRightHipRotateYJoint" type="revolute">
    <origin rpy="0 0 0" xyz="0.253 -0.051 0"/>
    <parent link="frontRightHipYBlock"/>
    <child link="frontRightHipRotateY"/>
    <axis xyz="0 1 0"/>
    <limit effort="150" lower="-3.14159265359" upper="3.14159265359" velocity="1.5"/>
    <sensor name="frontRightHipRotateYJoint_torque" type="force_torque">
      <update_rate>30</update_rate>
    </sensor>
  </joint>
  <!--GazeboControls-->
  <transmission name="frontRighttran2">
    <type>transmission_interface/SimpleTransmission</type>
    <joint name="frontRightHipRotateYJoint">
      <hardwareInterface>hardware_interface/EffortJointInterface</hardwareInterface>
    </joint>
    <actuator name="frontRightmotor2">
      <hardwareInterface>hardware_interface/EffortJointInterface</hardwareInterface>
      <mechanicalReduction>1</mechanicalReduction>
    </actuator>
  </transmission>
  <!--  hip bone is like the femur   -->
  <link name="frontRightFemur">
    <inertial>
      <mass value="0.3"/>
      <inertia ixx="6.125e-05" ixy="0.0" ixz="0.0" iyy="0.00106085" iyz="0.0" izz="0.00106085"/>
    </inertial>
    <visual>
      <origin rpy="0 0 0" xyz="0 -0.08099999999999999 -0.1015"/>
      <axis xyz="0 0 0"/>
      <geometry>
        <cylinder length="0.203" radius="0.035"/>
      </geometry>
      <material name="Cyan2">
        <color rgba="0.4 0.2 0.9 1.0"/>
      </material>
    </visual>
    <collision>
      <origin rpy="0 0 0" xyz="0 -0.08099999999999999 -0.1015"/>
      <axis xyz="0 0 0"/>
      <geometry>
        <cylinder length="0.203" radius="0.035"/>
      </geometry>
    </collision>
  </link>
  <joint name="frontRightFemurToHip" type="fixed">
    <parent link="frontRightHipRotateY"/>
    <child link="frontRightFemur"/>
    <origin rpy="0 0 0" xyz="0 0 0"/>
  </joint>
  <!--knee clevis-->
  <link name="frontRightKneeClevis">
    <inertial>
      <mass value="0.0001"/>
      <inertia ixx="1.5e-08" ixy="0.0" ixz="0.0" iyy="1.2918750000000001e-08" iyz="0.0" izz="1.2918750000000001e-08"/>
    </inertial>
    <visual>
      <origin rpy="1.5809 0 0" xyz="0 -0.14475000000000002 -0.203"/>
      <axis xyz="0 0 0"/>
      <geometry>
        <cylinder length="0.0255" radius="0.03"/>
      </geometry>
      <material name="Cyan1">
        <color rgba="0.3 0.15 0.9 1.0"/>
      </material>
    </visual>
    <collision>
      <origin rpy="1.5809 0 0" xyz="0 -0.14475000000000002 -0.203"/>
      <axis xyz="0 0 0"/>
      <geometry>
        <cylinder length="0.0255" radius="0.03"/>
      </geometry>
    </collision>
  </link>
  <joint name="frontRightKneeClevisFix" type="fixed">
    <origin rpy="0 0 0" xyz="0 0 0"/>
    <parent link="frontRightFemur"/>
    <child link="frontRightKneeClevis"/>
  </joint>
  <!--knee!-->
  <link name="frontRightKnee">
    <inertial>
      <mass value="0.01"/>
      <inertia ixx="1.4999999999999998e-06" ixy="0.0" ixz="0.0" iyy="9.419999999999998e-06" iyz="0.0" izz="9.419999999999998e-06"/>
    </inertial>
    <visual>
      <origin rpy="1.5809 0 0" xyz="0 -0.08099999999999999 0"/>
      <axis xyz="0 0 0"/>
      <geometry>
        <cylinder length="0.102" radius="0.03"/>
      </geometry>
      <material name="Cyan1">
        <color rgba="0.3 0.15 0.9 1.0"/>
      </material>
    </visual>
    <collision>
      <origin rpy="1.5809 0 0" xyz="0 -0.08099999999999999 0"/>
      <axis xyz="0 0 0"/>
      <geometry>
        <cylinder length="0.102" radius="0.03"/>
      </geometry>
    </collision>
  </link>
  <joint name="frontRightKneeJoint" type="revolute">
    <origin rpy="0 0 0" xyz="0 0 -0.203"/>
    <parent link="frontRightKneeClevis"/>
    <child link="frontRightKnee"/>
    <axis xyz="0 1 0"/>
    <limit effort="150" lower="-3.14159265359" upper="3.14159265359" velocity="1.5"/>
    <sensor name="frontRightKneeJoint_torque" type="force_torque">
      <update_rate>30</update_rate>
      <visualize>true</visualize>
      <always_on>true</always_on>
    </sensor>
  </joint>
  <!--GazeboControls-->
  <transmission name="frontRighttran3">
    <type>transmission_interface/SimpleTransmission</type>
    <joint name="frontRightKneeJoint">
      <hardwareInterface>hardware_interface/EffortJointInterface</hardwareInterface>
    </joint>
    <actuator name="frontRightmotor3">
      <hardwareInterface>hardware_interface/EffortJointInterface</hardwareInterface>
      <mechanicalReduction>1</mechanicalReduction>
    </actuator>
  </transmission>
  <!--Shin!-->
  <link name="frontRightShin">
    <inertial>
      <mass value="0.3"/>
      <inertia ixx="1.1249999999999999e-05" ixy="0.0" ixz="0.0" iyy="0.00068625" iyz="0.0" izz="0.00068625"/>
    </inertial>
    <visual>
      <origin rpy="0 0 0" xyz="0 -0.08099999999999999 -0.0825"/>
      <axis xyz="0 0 0"/>
      <geometry>
        <cylinder length="0.165" radius="0.015"/>
      </geometry>
      <material name="Green">
        <color rgba="0 1 0 1"/>
      </material>
    </visual>
    <collision>
      <origin rpy="0 0 0" xyz="0 -0.08099999999999999 -0.0825"/>
      <axis xyz="0 0 0"/>
      <geometry>
        <cylinder length="0.165" radius="0.015"/>
      </geometry>
    </collision>
  </link>
  <joint name="frontRightKneeToShin" type="fixed">
    <parent link="frontRightKnee"/>
    <child link="frontRightShin"/>
    <origin rpy="0 0 0" xyz="0 0 0"/>
  </joint>
  <!--FOOOOOOT-->
  <link name="frontRightFoot">
    <inertial>
      <mass value="0.126"/>
      <inertia ixx="2.1503999999999996e-05" ixy="0.0" ixz="0.0" iyy="2.1503999999999996e-05" iyz="0.0" izz="2.1503999999999996e-05"/>
    </inertial>
    <visual>
      <origin rpy="0 0 0" xyz="0 -0.08099999999999999 0"/>
      <geometry>
        <sphere radius="0.032"/>
      </geometry>
      <material name="Green">
        <color rgba="0 1 0 1"/>
      </material>
    </visual>
    <collision>
      </collision>
  </link>
  <gazebo reference="frontRightShin">
    <kp>1000000.0</kp>
    <kd>1.0</kd>
    <mu1>.8</mu1>
    <mu2>.8</mu2>
    <maxVel>0.0</maxVel>
    <minDepth>0.003</minDepth>
  </gazebo>
  <joint name="frontRightShinToFoot" type="fixed">
    <parent link="frontRightShin"/>
    <child link="frontRightFoot"/>
    <origin rpy="0 0 0.016" xyz="0 0 -0.181"/>
  </joint>
  <!--prefix is the legnumber, xReflext is  a 1 or -1 and same with yReflect this just mkaes it swtich locations for all 4 quadrents but why are you reading this is you arent me, if youre this deep in you got yourself in trouble run before its too late... I mean seriously I am writing an essay here stop scrolling to the side just keep reading the code and ignore the comments or I guess this one, some are helpful this one was until you got too nosy-->
  <link name="frontLeftHipBoxJointBearing">
    <inertial>
      <mass value="0.001"/>
      <inertia ixx="1.5e-07" ixy="0.0" ixz="0.0" iyy="2.0833333333333333e-07" iyz="0.0" izz="2.0833333333333333e-07"/>
    </inertial>
    <visual>
      <origin rpy="0 1.5809  0" xyz="0.151 0.102 0"/>
      <axis xyz="0 0 0"/>
      <geometry>
        <cylinder length="0.04" radius="0.03"/>
      </geometry>
      <material name="Cyan1">
        <color rgba="0.3 0.15 0.9 1.0"/>
      </material>
    </visual>
    <collision>
      <origin rpy="0 1.5809  0" xyz="0.151 0.102 0"/>
      <axis xyz="0 0 0"/>
      <geometry>
        <cylinder length="0.04" radius="0.03"/>
      </geometry>
    </collision>
  </link>
  <joint name="frontLeftBodyHipBoxFixedBearing" type="fixed">
    <parent link="dogBodyCross"/>
    <child link="frontLeftHipBoxJointBearing"/>
    <origin rpy="0 0 0" xyz="0 0 0"/>
  </joint>
  <!--X rotator allows for internal and external rotation-->
  <link name="frontLeftHipRotateX">
    <inertial>
      <mass value="0.3"/>
      <inertia ixx="4.4999999999999996e-05" ixy="0.0" ixz="0.0" iyy="0.00028259999999999993" iyz="0.0" izz="0.00028259999999999993"/>
    </inertial>
    <visual>
      <origin rpy="0 1.5809 0" xyz="0.242 0 0"/>
      <axis xyz="0 0 0"/>
      <geometry>
        <cylinder length="0.102" radius="0.03"/>
      </geometry>
      <material name="Cyan1">
        <color rgba="0.3 0.15 0.9 1.0"/>
      </material>
    </visual>
    <collision>
      <origin rpy="0 1.5809 0" xyz="0.242 0 0"/>
      <axis xyz="0 0 0"/>
      <geometry>
        <cylinder length="0.102" radius="0.03"/>
      </geometry>
    </collision>
  </link>
  <!--Joint from This Bone to the Main Body-->
  <joint name="frontLeftHipRotateXJoint" type="revolute">
    <parent link="frontLeftHipBoxJointBearing"/>
    <child link="frontLeftHipRotateX"/>
    <origin rpy="0 0 0" xyz="0 0.102 0"/>
    <axis xyz="1 0 0"/>
    <limit effort="150" lower="-3.14159265359" upper="3.14159265359" velocity="1.5"/>
    <sensor name="frontLeftHipRotateXJoint_torque" type="force_torque">
      <update_rate>30</update_rate>
    </sensor>
  </joint>
  <!--GazeboControls-->
  <transmission name="frontLefttran1">
    <type>transmission_interface/SimpleTransmission</type>
    <joint name="frontLeftHipRotateXJoint">
      <hardwareInterface>hardware_interface/EffortJointInterface</hardwareInterface>
    </joint>
    <actuator name="frontLeftmotor1">
      <hardwareInterface>hardware_interface/EffortJointInterface</hardwareInterface>
      <mechanicalReduction>1</mechanicalReduction>
    </actuator>
  </transmission>
  <!--Time to construct the hip box, makes me want to throw thousands into the march madness tournament, it will end differently this time I swear, massive value in the next Kentucky points over-->
  <!--Y block-->
  <link name="frontLeftHipYBlock">
    <inertial>
      <mass value="0.001"/>
      <inertia ixx="1.5e-07" ixy="0.0" ixz="0.0" iyy="3.7499999999999996e-07" iyz="0.0" izz="3.7499999999999996e-07"/>
    </inertial>
    <visual>
      <origin rpy="1.5809 0 0" xyz="0.253 0 0"/>
      <axis xyz="0 0 0"/>
      <geometry>
        <cylinder length="0.06" radius="0.03"/>
      </geometry>
      <material name="Cyan1">
        <color rgba="0.3 0.15 0.9 1.0"/>
      </material>
    </visual>
    <collision>
      <origin rpy="0 0 0" xyz="0.253 0 0"/>
      <axis xyz="0 0 0"/>
      <geometry>
        <cylinder length="0.06" radius="0.03"/>
      </geometry>
    </collision>
  </link>
  <joint name="frontLeftBodyHipBoxYAttach" type="fixed">
    <parent link="frontLeftHipRotateX"/>
    <child link="frontLeftHipYBlock"/>
    <origin rpy="0 0 0" xyz="0 0 0"/>
  </joint>
  <!--Y rotator allows for elevation and declanation rotation-->
  <link name="frontLeftHipRotateY">
    <inertial>
      <mass value="0.5"/>
      <inertia ixx="7.5e-05" ixy="0.0" ixz="0.0" iyy="0.0012701666666666664" iyz="0.0" izz="0.0012701666666666664"/>
    </inertial>
    <visual>
      <origin rpy="1.5809 0 0" xyz="0 0.03 0"/>
      <axis xyz="0 0 0"/>
      <geometry>
        <cylinder length="0.172" radius="0.03"/>
      </geometry>
      <material name="Cyan1">
        <color rgba="0.3 0.15 0.9 1.0"/>
      </material>
    </visual>
    <collision>
      <origin rpy="1.5809 0 0" xyz="0 0.03 0"/>
      <axis xyz="0 0 0"/>
      <geometry>
        <cylinder length="0.102" radius="0.03"/>
      </geometry>
    </collision>
  </link>
  <joint name="frontLeftHipRotateYJoint" type="revolute">
    <origin rpy="0 0 0" xyz="0.253 0.051 0"/>
    <parent link="frontLeftHipYBlock"/>
    <child link="frontLeftHipRotateY"/>
    <axis xyz="0 1 0"/>
    <limit effort="150" lower="-3.14159265359" upper="3.14159265359" velocity="1.5"/>
    <sensor name="frontLeftHipRotateYJoint_torque" type="force_torque">
      <update_rate>30</update_rate>
    </sensor>
  </joint>
  <!--GazeboControls-->
  <transmission name="frontLefttran2">
    <type>transmission_interface/SimpleTransmission</type>
    <joint name="frontLeftHipRotateYJoint">
      <hardwareInterface>hardware_interface/EffortJointInterface</hardwareInterface>
    </joint>
    <actuator name="frontLeftmotor2">
      <hardwareInterface>hardware_interface/EffortJointInterface</hardwareInterface>
      <mechanicalReduction>1</mechanicalReduction>
    </actuator>
  </transmission>
  <!--  hip bone is like the femur   -->
  <link name="frontLeftFemur">
    <inertial>
      <mass value="0.3"/>
      <inertia ixx="6.125e-05" ixy="0.0" ixz="0.0" iyy="0.00106085" iyz="0.0" izz="0.00106085"/>
    </inertial>
    <visual>
      <origin rpy="0 0 0" xyz="0 0.08099999999999999 -0.1015"/>
      <axis xyz="0 0 0"/>
      <geometry>
        <cylinder length="0.203" radius="0.035"/>
      </geometry>
      <material name="Cyan2">
        <color rgba="0.4 0.2 0.9 1.0"/>
      </material>
    </visual>
    <collision>
      <origin rpy="0 0 0" xyz="0 0.08099999999999999 -0.1015"/>
      <axis xyz="0 0 0"/>
      <geometry>
        <cylinder length="0.203" radius="0.035"/>
      </geometry>
    </collision>
  </link>
  <joint name="frontLeftFemurToHip" type="fixed">
    <parent link="frontLeftHipRotateY"/>
    <child link="frontLeftFemur"/>
    <origin rpy="0 0 0" xyz="0 0 0"/>
  </joint>
  <!--knee clevis-->
  <link name="frontLeftKneeClevis">
    <inertial>
      <mass value="0.0001"/>
      <inertia ixx="1.5e-08" ixy="0.0" ixz="0.0" iyy="1.2918750000000001e-08" iyz="0.0" izz="1.2918750000000001e-08"/>
    </inertial>
    <visual>
      <origin rpy="1.5809 0 0" xyz="0 0.14475000000000002 -0.203"/>
      <axis xyz="0 0 0"/>
      <geometry>
        <cylinder length="0.0255" radius="0.03"/>
      </geometry>
      <material name="Cyan1">
        <color rgba="0.3 0.15 0.9 1.0"/>
      </material>
    </visual>
    <collision>
      <origin rpy="1.5809 0 0" xyz="0 0.14475000000000002 -0.203"/>
      <axis xyz="0 0 0"/>
      <geometry>
        <cylinder length="0.0255" radius="0.03"/>
      </geometry>
    </collision>
  </link>
  <joint name="frontLeftKneeClevisFix" type="fixed">
    <origin rpy="0 0 0" xyz="0 0 0"/>
    <parent link="frontLeftFemur"/>
    <child link="frontLeftKneeClevis"/>
  </joint>
  <!--knee!-->
  <link name="frontLeftKnee">
    <inertial>
      <mass value="0.01"/>
      <inertia ixx="1.4999999999999998e-06" ixy="0.0" ixz="0.0" iyy="9.419999999999998e-06" iyz="0.0" izz="9.419999999999998e-06"/>
    </inertial>
    <visual>
      <origin rpy="1.5809 0 0" xyz="0 0.08099999999999999 0"/>
      <axis xyz="0 0 0"/>
      <geometry>
        <cylinder length="0.102" radius="0.03"/>
      </geometry>
      <material name="Cyan1">
        <color rgba="0.3 0.15 0.9 1.0"/>
      </material>
    </visual>
    <collision>
      <origin rpy="1.5809 0 0" xyz="0 0.08099999999999999 0"/>
      <axis xyz="0 0 0"/>
      <geometry>
        <cylinder length="0.102" radius="0.03"/>
      </geometry>
    </collision>
  </link>
  <joint name="frontLeftKneeJoint" type="revolute">
    <origin rpy="0 0 0" xyz="0 0 -0.203"/>
    <parent link="frontLeftKneeClevis"/>
    <child link="frontLeftKnee"/>
    <axis xyz="0 1 0"/>
    <limit effort="150" lower="-3.14159265359" upper="3.14159265359" velocity="1.5"/>
    <sensor name="frontLeftKneeJoint_torque" type="force_torque">
      <update_rate>30</update_rate>
    </sensor>
  </joint>
  <!--GazeboControls-->
  <transmission name="frontLefttran3">
    <type>transmission_interface/SimpleTransmission</type>
    <joint name="frontLeftKneeJoint">
      <hardwareInterface>hardware_interface/EffortJointInterface</hardwareInterface>
    </joint>
    <actuator name="frontLeftmotor3">
      <hardwareInterface>hardware_interface/EffortJointInterface</hardwareInterface>
      <mechanicalReduction>1</mechanicalReduction>
    </actuator>
  </transmission>
  <!--Shin!-->
  <link name="frontLeftShin">
    <inertial>
      <mass value="0.3"/>
      <inertia ixx="1.1249999999999999e-05" ixy="0.0" ixz="0.0" iyy="0.00068625" iyz="0.0" izz="0.00068625"/>
    </inertial>
    <visual>
      <origin rpy="0 0 0" xyz="0 0.08099999999999999 -0.0825"/>
      <axis xyz="0 0 0"/>
      <geometry>
        <cylinder length="0.165" radius="0.015"/>
      </geometry>
      <material name="Green">
        <color rgba="0 1 0 1"/>
      </material>
    </visual>
    <collision>
      <origin rpy="0 0 0" xyz="0 0.08099999999999999 -0.0825"/>
      <axis xyz="0 0 0"/>
      <geometry>
        <cylinder length="0.165" radius="0.015"/>
      </geometry>
    </collision>
  </link>
  <joint name="frontLeftKneeToShin" type="fixed">
    <parent link="frontLeftKnee"/>
    <child link="frontLeftShin"/>
    <origin rpy="0 0 0" xyz="0 0 0"/>
  </joint>
  <!--FOOOOOOT-->
  <link name="frontLeftFoot">
    <inertial>
      <mass value="0.126"/>
      <inertia ixx="2.1503999999999996e-05" ixy="0.0" ixz="0.0" iyy="2.1503999999999996e-05" iyz="0.0" izz="2.1503999999999996e-05"/>
    </inertial>
    <visual>
      <origin rpy="0 0 0" xyz="0 0.08099999999999999 0"/>
      <geometry>
        <sphere radius="0.032"/>
      </geometry>
      <material name="Green">
        <color rgba="0 1 0 1"/>
      </material>
    </visual>
    <collision>
      </collision>
  </link>
  <gazebo reference="frontLeftShin">
    <kp>1000000.0</kp>
    <kd>1.0</kd>
    <mu1>.8</mu1>
    <mu2>.8</mu2>
    <maxVel>0.0</maxVel>
    <minDepth>0.003</minDepth>
  </gazebo>
  <joint name="frontLeftShinToFoot" type="fixed">
    <parent link="frontLeftShin"/>
    <child link="frontLeftFoot"/>
    <origin rpy="0 0 0.016" xyz="0 0 -0.181"/>
  </joint>
  <!--prefix is the legnumber, xReflext is  a 1 or -1 and same with yReflect this just mkaes it swtich locations for all 4 quadrents but why are you reading this is you arent me, if youre this deep in you got yourself in trouble run before its too late... I mean seriously I am writing an essay here stop scrolling to the side just keep reading the code and ignore the comments or I guess this one, some are helpful this one was until you got too nosy-->
  <link name="backRightHipBoxJointBearing">
    <inertial>
      <mass value="0.001"/>
      <inertia ixx="1.5e-07" ixy="0.0" ixz="0.0" iyy="2.0833333333333333e-07" iyz="0.0" izz="2.0833333333333333e-07"/>
    </inertial>
    <visual>
      <origin rpy="0 1.5809  0" xyz="-0.151 -0.102 0"/>
      <axis xyz="0 0 0"/>
      <geometry>
        <cylinder length="0.04" radius="0.03"/>
      </geometry>
      <material name="Cyan1">
        <color rgba="0.3 0.15 0.9 1.0"/>
      </material>
    </visual>
    <collision>
      <origin rpy="0 1.5809  0" xyz="-0.151 -0.102 0"/>
      <axis xyz="0 0 0"/>
      <geometry>
        <cylinder length="0.04" radius="0.03"/>
      </geometry>
    </collision>
  </link>
  <joint name="backRightBodyHipBoxFixedBearing" type="fixed">
    <parent link="dogBodyCross"/>
    <child link="backRightHipBoxJointBearing"/>
    <origin rpy="0 0 0" xyz="0 0 0"/>
  </joint>
  <!--X rotator allows for internal and external rotation-->
  <link name="backRightHipRotateX">
    <inertial>
      <mass value="0.3"/>
      <inertia ixx="4.4999999999999996e-05" ixy="0.0" ixz="0.0" iyy="0.00028259999999999993" iyz="0.0" izz="0.00028259999999999993"/>
    </inertial>
    <visual>
      <origin rpy="0 1.5809 0" xyz="-0.242 0 0"/>
      <axis xyz="0 0 0"/>
      <geometry>
        <cylinder length="0.102" radius="0.03"/>
      </geometry>
      <material name="Cyan1">
        <color rgba="0.3 0.15 0.9 1.0"/>
      </material>
    </visual>
    <collision>
      <origin rpy="0 1.5809 0" xyz="-0.242 0 0"/>
      <axis xyz="0 0 0"/>
      <geometry>
        <cylinder length="0.102" radius="0.03"/>
      </geometry>
    </collision>
  </link>
  <!--Joint from This Bone to the Main Body-->
  <joint name="backRightHipRotateXJoint" type="revolute">
    <parent link="backRightHipBoxJointBearing"/>
    <child link="backRightHipRotateX"/>
    <origin rpy="0 0 0" xyz="0 -0.102 0"/>
    <axis xyz="1 0 0"/>
    <limit effort="150" lower="-3.14159265359" upper="3.14159265359" velocity="1.5"/>
    <sensor name="backRightHipRotateXJoint_torque" type="force_torque">
      <update_rate>30</update_rate>
    </sensor>
  </joint>
  <!--GazeboControls-->
  <transmission name="backRighttran1">
    <type>transmission_interface/SimpleTransmission</type>
    <joint name="backRightHipRotateXJoint">
      <hardwareInterface>hardware_interface/EffortJointInterface</hardwareInterface>
    </joint>
    <actuator name="backRightmotor1">
      <hardwareInterface>hardware_interface/EffortJointInterface</hardwareInterface>
      <mechanicalReduction>1</mechanicalReduction>
    </actuator>
  </transmission>
  <!--Time to construct the hip box, makes me want to throw thousands into the march madness tournament, it will end differently this time I swear, massive value in the next Kentucky points over-->
  <!--Y block-->
  <link name="backRightHipYBlock">
    <inertial>
      <mass value="0.001"/>
      <inertia ixx="1.5e-07" ixy="0.0" ixz="0.0" iyy="3.7499999999999996e-07" iyz="0.0" izz="3.7499999999999996e-07"/>
    </inertial>
    <visual>
      <origin rpy="1.5809 0 0" xyz="-0.253 0 0"/>
      <axis xyz="0 0 0"/>
      <geometry>
        <cylinder length="0.06" radius="0.03"/>
      </geometry>
      <material name="Cyan1">
        <color rgba="0.3 0.15 0.9 1.0"/>
      </material>
    </visual>
    <collision>
      <origin rpy="0 0 0" xyz="-0.253 0 0"/>
      <axis xyz="0 0 0"/>
      <geometry>
        <cylinder length="0.06" radius="0.03"/>
      </geometry>
    </collision>
  </link>
  <joint name="backRightBodyHipBoxYAttach" type="fixed">
    <parent link="backRightHipRotateX"/>
    <child link="backRightHipYBlock"/>
    <origin rpy="0 0 0" xyz="0 0 0"/>
  </joint>
  <!--Y rotator allows for elevation and declanation rotation-->
  <link name="backRightHipRotateY">
    <inertial>
      <mass value="0.5"/>
      <inertia ixx="7.5e-05" ixy="0.0" ixz="0.0" iyy="0.0012701666666666664" iyz="0.0" izz="0.0012701666666666664"/>
    </inertial>
    <visual>
      <origin rpy="1.5809 0 0" xyz="0 -0.03 0"/>
      <axis xyz="0 0 0"/>
      <geometry>
        <cylinder length="0.172" radius="0.03"/>
      </geometry>
      <material name="Cyan1">
        <color rgba="0.3 0.15 0.9 1.0"/>
      </material>
    </visual>
    <collision>
      <origin rpy="1.5809 0 0" xyz="0 -0.03 0"/>
      <axis xyz="0 0 0"/>
      <geometry>
        <cylinder length="0.102" radius="0.03"/>
      </geometry>
    </collision>
  </link>
  <joint name="backRightHipRotateYJoint" type="revolute">
    <origin rpy="0 0 0" xyz="-0.253 -0.051 0"/>
    <parent link="backRightHipYBlock"/>
    <child link="backRightHipRotateY"/>
    <axis xyz="0 1 0"/>
    <limit effort="150" lower="-3.14159265359" upper="3.14159265359" velocity="1.5"/>
    <sensor name="backRightHipRotateYJoint_torque" type="force_torque">
      <update_rate>30</update_rate>
    </sensor>
  </joint>
  <!--GazeboControls-->
  <transmission name="backRighttran2">
    <type>transmission_interface/SimpleTransmission</type>
    <joint name="backRightHipRotateYJoint">
      <hardwareInterface>hardware_interface/EffortJointInterface</hardwareInterface>
    </joint>
    <actuator name="backRightmotor2">
      <hardwareInterface>hardware_interface/EffortJointInterface</hardwareInterface>
      <mechanicalReduction>1</mechanicalReduction>
    </actuator>
  </transmission>
  <!--  hip bone is like the femur   -->
  <link name="backRightFemur">
    <inertial>
      <mass value="0.3"/>
      <inertia ixx="6.125e-05" ixy="0.0" ixz="0.0" iyy="0.00106085" iyz="0.0" izz="0.00106085"/>
    </inertial>
    <visual>
      <origin rpy="0 0 0" xyz="0 -0.08099999999999999 -0.1015"/>
      <axis xyz="0 0 0"/>
      <geometry>
        <cylinder length="0.203" radius="0.035"/>
      </geometry>
      <material name="Cyan2">
        <color rgba="0.4 0.2 0.9 1.0"/>
      </material>
    </visual>
    <collision>
      <origin rpy="0 0 0" xyz="0 -0.08099999999999999 -0.1015"/>
      <axis xyz="0 0 0"/>
      <geometry>
        <cylinder length="0.203" radius="0.035"/>
      </geometry>
    </collision>
  </link>
  <joint name="backRightFemurToHip" type="fixed">
    <parent link="backRightHipRotateY"/>
    <child link="backRightFemur"/>
    <origin rpy="0 0 0" xyz="0 0 0"/>
  </joint>
  <!--knee clevis-->
  <link name="backRightKneeClevis">
    <inertial>
      <mass value="0.0001"/>
      <inertia ixx="1.5e-08" ixy="0.0" ixz="0.0" iyy="1.2918750000000001e-08" iyz="0.0" izz="1.2918750000000001e-08"/>
    </inertial>
    <visual>
      <origin rpy="1.5809 0 0" xyz="0 -0.14475000000000002 -0.203"/>
      <axis xyz="0 0 0"/>
      <geometry>
        <cylinder length="0.0255" radius="0.03"/>
      </geometry>
      <material name="Cyan1">
        <color rgba="0.3 0.15 0.9 1.0"/>
      </material>
    </visual>
    <collision>
      <origin rpy="1.5809 0 0" xyz="0 -0.14475000000000002 -0.203"/>
      <axis xyz="0 0 0"/>
      <geometry>
        <cylinder length="0.0255" radius="0.03"/>
      </geometry>
    </collision>
  </link>
  <joint name="backRightKneeClevisFix" type="fixed">
    <origin rpy="0 0 0" xyz="0 0 0"/>
    <parent link="backRightFemur"/>
    <child link="backRightKneeClevis"/>
  </joint>
  <!--knee!-->
  <link name="backRightKnee">
    <inertial>
      <mass value="0.01"/>
      <inertia ixx="1.4999999999999998e-06" ixy="0.0" ixz="0.0" iyy="9.419999999999998e-06" iyz="0.0" izz="9.419999999999998e-06"/>
    </inertial>
    <visual>
      <origin rpy="1.5809 0 0" xyz="0 -0.08099999999999999 0"/>
      <axis xyz="0 0 0"/>
      <geometry>
        <cylinder length="0.102" radius="0.03"/>
      </geometry>
      <material name="Cyan1">
        <color rgba="0.3 0.15 0.9 1.0"/>
      </material>
    </visual>
    <collision>
      <origin rpy="1.5809 0 0" xyz="0 -0.08099999999999999 0"/>
      <axis xyz="0 0 0"/>
      <geometry>
        <cylinder length="0.102" radius="0.03"/>
      </geometry>
    </collision>
  </link>
  <joint name="backRightKneeJoint" type="revolute">
    <origin rpy="0 0 0" xyz="0 0 -0.203"/>
    <parent link="backRightKneeClevis"/>
    <child link="backRightKnee"/>
    <axis xyz="0 1 0"/>
    <limit effort="150" lower="-3.14159265359" upper="3.14159265359" velocity="1.5"/>
    <sensor name="backRightKneeJoint_torque" type="force_torque">
      <update_rate>30</update_rate>
    </sensor>
  </joint>
  <!--GazeboControls-->
  <transmission name="backRighttran3">
    <type>transmission_interface/SimpleTransmission</type>
    <joint name="backRightKneeJoint">
      <hardwareInterface>hardware_interface/EffortJointInterface</hardwareInterface>
    </joint>
    <actuator name="backRightmotor3">
      <hardwareInterface>hardware_interface/EffortJointInterface</hardwareInterface>
      <mechanicalReduction>1</mechanicalReduction>
    </actuator>
  </transmission>
  <!--Shin!-->
  <link name="backRightShin">
    <inertial>
      <mass value="0.3"/>
      <inertia ixx="1.1249999999999999e-05" ixy="0.0" ixz="0.0" iyy="0.00068625" iyz="0.0" izz="0.00068625"/>
    </inertial>
    <visual>
      <origin rpy="0 0 0" xyz="0 -0.08099999999999999 -0.0825"/>
      <axis xyz="0 0 0"/>
      <geometry>
        <cylinder length="0.165" radius="0.015"/>
      </geometry>
      <material name="Green">
        <color rgba="0 1 0 1"/>
      </material>
    </visual>
    <collision>
      <origin rpy="0 0 0" xyz="0 -0.08099999999999999 -0.0825"/>
      <axis xyz="0 0 0"/>
      <geometry>
        <cylinder length="0.165" radius="0.015"/>
      </geometry>
    </collision>
  </link>
  <joint name="backRightKneeToShin" type="fixed">
    <parent link="backRightKnee"/>
    <child link="backRightShin"/>
    <origin rpy="0 0 0" xyz="0 0 0"/>
  </joint>
  <!--FOOOOOOT-->
  <link name="backRightFoot">
    <inertial>
      <mass value="0.126"/>
      <inertia ixx="2.1503999999999996e-05" ixy="0.0" ixz="0.0" iyy="2.1503999999999996e-05" iyz="0.0" izz="2.1503999999999996e-05"/>
    </inertial>
    <visual>
      <origin rpy="0 0 0" xyz="0 -0.08099999999999999 0"/>
      <geometry>
        <sphere radius="0.032"/>
      </geometry>
      <material name="Green">
        <color rgba="0 1 0 1"/>
      </material>
    </visual>
    <collision>
      </collision>
  </link>
  <gazebo reference="backRightShin">
    <kp>1000000.0</kp>
    <kd>1.0</kd>
    <mu1>.8</mu1>
    <mu2>.8</mu2>
    <maxVel>0.0</maxVel>
    <minDepth>0.003</minDepth>
  </gazebo>
  <joint name="backRightShinToFoot" type="fixed">
    <parent link="backRightShin"/>
    <child link="backRightFoot"/>
    <origin rpy="0 0 0.016" xyz="0 0 -0.181"/>
  </joint>
  <!--prefix is the legnumber, xReflext is  a 1 or -1 and same with yReflect this just mkaes it swtich locations for all 4 quadrents but why are you reading this is you arent me, if youre this deep in you got yourself in trouble run before its too late... I mean seriously I am writing an essay here stop scrolling to the side just keep reading the code and ignore the comments or I guess this one, some are helpful this one was until you got too nosy-->
  <link name="backLeftHipBoxJointBearing">
    <inertial>
      <mass value="0.001"/>
      <inertia ixx="1.5e-07" ixy="0.0" ixz="0.0" iyy="2.0833333333333333e-07" iyz="0.0" izz="2.0833333333333333e-07"/>
    </inertial>
    <visual>
      <origin rpy="0 1.5809  0" xyz="-0.151 0.102 0"/>
      <axis xyz="0 0 0"/>
      <geometry>
        <cylinder length="0.04" radius="0.03"/>
      </geometry>
      <material name="Cyan1">
        <color rgba="0.3 0.15 0.9 1.0"/>
      </material>
    </visual>
    <collision>
      <origin rpy="0 1.5809  0" xyz="-0.151 0.102 0"/>
      <axis xyz="0 0 0"/>
      <geometry>
        <cylinder length="0.04" radius="0.03"/>
      </geometry>
    </collision>
  </link>
  <joint name="backLeftBodyHipBoxFixedBearing" type="fixed">
    <parent link="dogBodyCross"/>
    <child link="backLeftHipBoxJointBearing"/>
    <origin rpy="0 0 0" xyz="0 0 0"/>
  </joint>
  <!--X rotator allows for internal and external rotation-->
  <link name="backLeftHipRotateX">
    <inertial>
      <mass value="0.3"/>
      <inertia ixx="4.4999999999999996e-05" ixy="0.0" ixz="0.0" iyy="0.00028259999999999993" iyz="0.0" izz="0.00028259999999999993"/>
    </inertial>
    <visual>
      <origin rpy="0 1.5809 0" xyz="-0.242 0 0"/>
      <axis xyz="0 0 0"/>
      <geometry>
        <cylinder length="0.102" radius="0.03"/>
      </geometry>
      <material name="Cyan1">
        <color rgba="0.3 0.15 0.9 1.0"/>
      </material>
    </visual>
    <collision>
      <origin rpy="0 1.5809 0" xyz="-0.242 0 0"/>
      <axis xyz="0 0 0"/>
      <geometry>
        <cylinder length="0.102" radius="0.03"/>
      </geometry>
    </collision>
  </link>
  <!--Joint from This Bone to the Main Body-->
  <joint name="backLeftHipRotateXJoint" type="revolute">
    <parent link="backLeftHipBoxJointBearing"/>
    <child link="backLeftHipRotateX"/>
    <origin rpy="0 0 0" xyz="0 0.102 0"/>
    <axis xyz="1 0 0"/>
    <limit effort="150" lower="-3.14159265359" upper="3.14159265359" velocity="1.5"/>
    <sensor name="backLeftHipRotateXJoint_torque" type="force_torque">
      <update_rate>30</update_rate>
    </sensor>
  </joint>
  <!--GazeboControls-->
  <transmission name="backLefttran1">
    <type>transmission_interface/SimpleTransmission</type>
    <joint name="backLeftHipRotateXJoint">
      <hardwareInterface>hardware_interface/EffortJointInterface</hardwareInterface>
    </joint>
    <actuator name="backLeftmotor1">
      <hardwareInterface>hardware_interface/EffortJointInterface</hardwareInterface>
      <mechanicalReduction>1</mechanicalReduction>
    </actuator>
  </transmission>
  <!--Time to construct the hip box, makes me want to throw thousands into the march madness tournament, it will end differently this time I swear, massive value in the next Kentucky points over-->
  <!--Y block-->
  <link name="backLeftHipYBlock">
    <inertial>
      <mass value="0.001"/>
      <inertia ixx="1.5e-07" ixy="0.0" ixz="0.0" iyy="3.7499999999999996e-07" iyz="0.0" izz="3.7499999999999996e-07"/>
    </inertial>
    <visual>
      <origin rpy="1.5809 0 0" xyz="-0.253 0 0"/>
      <axis xyz="0 0 0"/>
      <geometry>
        <cylinder length="0.06" radius="0.03"/>
      </geometry>
      <material name="Cyan1">
        <color rgba="0.3 0.15 0.9 1.0"/>
      </material>
    </visual>
    <collision>
      <origin rpy="0 0 0" xyz="-0.253 0 0"/>
      <axis xyz="0 0 0"/>
      <geometry>
        <cylinder length="0.06" radius="0.03"/>
      </geometry>
    </collision>
  </link>
  <joint name="backLeftBodyHipBoxYAttach" type="fixed">
    <parent link="backLeftHipRotateX"/>
    <child link="backLeftHipYBlock"/>
    <origin rpy="0 0 0" xyz="0 0 0"/>
  </joint>
  <!--Y rotator allows for elevation and declanation rotation-->
  <link name="backLeftHipRotateY">
    <inertial>
      <mass value="0.5"/>
      <inertia ixx="7.5e-05" ixy="0.0" ixz="0.0" iyy="0.0012701666666666664" iyz="0.0" izz="0.0012701666666666664"/>
    </inertial>
    <visual>
      <origin rpy="1.5809 0 0" xyz="0 0.03 0"/>
      <axis xyz="0 0 0"/>
      <geometry>
        <cylinder length="0.172" radius="0.03"/>
      </geometry>
      <material name="Cyan1">
        <color rgba="0.3 0.15 0.9 1.0"/>
      </material>
    </visual>
    <collision>
      <origin rpy="1.5809 0 0" xyz="0 0.03 0"/>
      <axis xyz="0 0 0"/>
      <geometry>
        <cylinder length="0.102" radius="0.03"/>
      </geometry>
    </collision>
  </link>
  <joint name="backLeftHipRotateYJoint" type="revolute">
    <origin rpy="0 0 0" xyz="-0.253 0.051 0"/>
    <parent link="backLeftHipYBlock"/>
    <child link="backLeftHipRotateY"/>
    <axis xyz="0 1 0"/>
    <limit effort="150" lower="-3.14159265359" upper="3.14159265359" velocity="1.5"/>
    <sensor name="backLeftHipRotateYJoint_torque" type="force_torque">
      <update_rate>30</update_rate>
    </sensor>
  </joint>
  <!--GazeboControls-->
  <transmission name="backLefttran2">
    <type>transmission_interface/SimpleTransmission</type>
    <joint name="backLeftHipRotateYJoint">
      <hardwareInterface>hardware_interface/EffortJointInterface</hardwareInterface>
    </joint>
    <actuator name="backLeftmotor2">
      <hardwareInterface>hardware_interface/EffortJointInterface</hardwareInterface>
      <mechanicalReduction>1</mechanicalReduction>
    </actuator>
  </transmission>
  <!--  hip bone is like the femur   -->
  <link name="backLeftFemur">
    <inertial>
      <mass value="0.3"/>
      <inertia ixx="6.125e-05" ixy="0.0" ixz="0.0" iyy="0.00106085" iyz="0.0" izz="0.00106085"/>
    </inertial>
    <visual>
      <origin rpy="0 0 0" xyz="0 0.08099999999999999 -0.1015"/>
      <axis xyz="0 0 0"/>
      <geometry>
        <cylinder length="0.203" radius="0.035"/>
      </geometry>
      <material name="Cyan2">
        <color rgba="0.4 0.2 0.9 1.0"/>
      </material>
    </visual>
    <collision>
      <origin rpy="0 0 0" xyz="0 0.08099999999999999 -0.1015"/>
      <axis xyz="0 0 0"/>
      <geometry>
        <cylinder length="0.203" radius="0.035"/>
      </geometry>
    </collision>
  </link>
  <joint name="backLeftFemurToHip" type="fixed">
    <parent link="backLeftHipRotateY"/>
    <child link="backLeftFemur"/>
    <origin rpy="0 0 0" xyz="0 0 0"/>
  </joint>
  <!--knee clevis-->
  <link name="backLeftKneeClevis">
    <inertial>
      <mass value="0.0001"/>
      <inertia ixx="1.5e-08" ixy="0.0" ixz="0.0" iyy="1.2918750000000001e-08" iyz="0.0" izz="1.2918750000000001e-08"/>
    </inertial>
    <visual>
      <origin rpy="1.5809 0 0" xyz="0 0.14475000000000002 -0.203"/>
      <axis xyz="0 0 0"/>
      <geometry>
        <cylinder length="0.0255" radius="0.03"/>
      </geometry>
      <material name="Cyan1">
        <color rgba="0.3 0.15 0.9 1.0"/>
      </material>
    </visual>
    <collision>
      <origin rpy="1.5809 0 0" xyz="0 0.14475000000000002 -0.203"/>
      <axis xyz="0 0 0"/>
      <geometry>
        <cylinder length="0.0255" radius="0.03"/>
      </geometry>
    </collision>
  </link>
  <joint name="backLeftKneeClevisFix" type="fixed">
    <origin rpy="0 0 0" xyz="0 0 0"/>
    <parent link="backLeftFemur"/>
    <child link="backLeftKneeClevis"/>
  </joint>
  <!--knee!-->
  <link name="backLeftKnee">
    <inertial>
      <mass value="0.01"/>
      <inertia ixx="1.4999999999999998e-06" ixy="0.0" ixz="0.0" iyy="9.419999999999998e-06" iyz="0.0" izz="9.419999999999998e-06"/>
    </inertial>
    <visual>
      <origin rpy="1.5809 0 0" xyz="0 0.08099999999999999 0"/>
      <axis xyz="0 0 0"/>
      <geometry>
        <cylinder length="0.102" radius="0.03"/>
      </geometry>
      <material name="Cyan1">
        <color rgba="0.3 0.15 0.9 1.0"/>
      </material>
    </visual>
    <collision>
      <origin rpy="1.5809 0 0" xyz="0 0.08099999999999999 0"/>
      <axis xyz="0 0 0"/>
      <geometry>
        <cylinder length="0.102" radius="0.03"/>
      </geometry>
    </collision>
  </link>
  <joint name="backLeftKneeJoint" type="revolute">
    <origin rpy="0 0 0" xyz="0 0 -0.203"/>
    <parent link="backLeftKneeClevis"/>
    <child link="backLeftKnee"/>
    <axis xyz="0 1 0"/>
    <limit effort="150" lower="-3.14159265359" upper="3.14159265359" velocity="1.5"/>
    <sensor name="backLeftKneeJoint_torque" type="force_torque">
      <update_rate>30</update_rate>
    </sensor>
  </joint>
  <!--GazeboControls-->
  <transmission name="backLefttran3">
    <type>transmission_interface/SimpleTransmission</type>
    <joint name="backLeftKneeJoint">
      <hardwareInterface>hardware_interface/EffortJointInterface</hardwareInterface>
    </joint>
    <actuator name="backLeftmotor3">
      <hardwareInterface>hardware_interface/EffortJointInterface</hardwareInterface>
      <mechanicalReduction>1</mechanicalReduction>
    </actuator>
  </transmission>
  <!--Shin!-->
  <link name="backLeftShin">
    <inertial>
      <mass value="0.3"/>
      <inertia ixx="1.1249999999999999e-05" ixy="0.0" ixz="0.0" iyy="0.00068625" iyz="0.0" izz="0.00068625"/>
    </inertial>
    <visual>
      <origin rpy="0 0 0" xyz="0 0.08099999999999999 -0.0825"/>
      <axis xyz="0 0 0"/>
      <geometry>
        <cylinder length="0.165" radius="0.015"/>
      </geometry>
      <material name="Green">
        <color rgba="0 1 0 1"/>
      </material>
    </visual>
    <collision>
      <origin rpy="0 0 0" xyz="0 0.08099999999999999 -0.0825"/>
      <axis xyz="0 0 0"/>
      <geometry>
        <cylinder length="0.165" radius="0.015"/>
      </geometry>
    </collision>
  </link>
  <joint name="backLeftKneeToShin" type="fixed">
    <parent link="backLeftKnee"/>
    <child link="backLeftShin"/>
    <origin rpy="0 0 0" xyz="0 0 0"/>
  </joint>
  <!--FOOOOOOT-->
  <link name="backLeftFoot">
    <inertial>
      <mass value="0.126"/>
      <inertia ixx="2.1503999999999996e-05" ixy="0.0" ixz="0.0" iyy="2.1503999999999996e-05" iyz="0.0" izz="2.1503999999999996e-05"/>
    </inertial>
    <visual>
      <origin rpy="0 0 0" xyz="0 0.08099999999999999 0"/>
      <geometry>
        <sphere radius="0.032"/>
      </geometry>
      <material name="Green">
        <color rgba="0 1 0 1"/>
      </material>
    </visual>
    <collision>
      </collision>
  </link>
  <gazebo reference="backLeftShin">
    <kp>1000000.0</kp>
    <kd>1.0</kd>
    <mu1>.8</mu1>
    <mu2>.8</mu2>
    <maxVel>0.0</maxVel>
    <minDepth>0.003</minDepth>
  </gazebo>
  <joint name="backLeftShinToFoot" type="fixed">
    <parent link="backLeftShin"/>
    <child link="backLeftFoot"/>
    <origin rpy="0 0 0.016" xyz="0 0 -0.181"/>
  </joint>
  <gazebo>
    <plugin filename="libgazebo_ros_control.so" name="gazebo_ros_control">
      <legacyModeNS>true</legacyModeNS>
    </plugin>
  </gazebo>
  <link name="hokuyo_frame">
    <inertial>
      <mass value="0.270"/>
      <origin rpy="0 0 0" xyz="0 0 0"/>
      <inertia ixx="2.632e-4" ixy="0" ixz="0" iyy="2.632e-4" iyz="0" izz="1.62e-4"/>
    </inertial>
    <visual>
      <origin rpy="0 0 0" xyz="0 0 0"/>
      <geometry>
        <mesh filename="package://hector_sensors_description/meshes/hokuyo_utm30lx/hokuyo_utm_30lx.dae"/>
      </geometry>
    </visual>
    <collision>
      <origin rpy="0 0 0" xyz="0 0 -0.0115"/>
      <geometry>
        <box size="0.058 0.058 0.087"/>
        <!--<mesh filename="package://hector_sensors_description/meshes/hokuyo_utm30lx/hokuyo_utm_30lx.stl"/>-->
      </geometry>
    </collision>
  </link>
  <joint name="hokuyo_joint" type="fixed">
    <origin rpy="0 0 0" xyz="0.4 0.0 0.2"/>
    <parent link="base_link"/>
    <child link="hokuyo_frame"/>
  </joint>
  <gazebo reference="hokuyo_frame">
    <sensor name="hokuyo" type="ray">
      <always_on>true</always_on>
      <update_rate>30</update_rate>
      <pose>0 0 0 0 0 0</pose>
      <visualize>false</visualize>
      <ray>
        <scan>
          <horizontal>
            <samples>1040</samples>
            <resolution>1</resolution>
            <min_angle>2.26892802759</min_angle>
            <max_angle>-2.26892802759</max_angle>
          </horizontal>
        </scan>
        <range>
          <min>0.2</min>
          <max>30.0</max>
          <resolution>0.01</resolution>
        </range>
        <noise>
          <type>gaussian</type>
          <mean>0.0</mean>
          <stddev>0.004</stddev>
        </noise>
      </ray>
      <plugin filename="libgazebo_ros_laser.so" name="gazebo_ros_hokuyo_controller">
        <topicName>scan</topicName>
        <frameName>hokuyo_frame</frameName>
      </plugin>
    </sensor>
  </gazebo>
  <joint name="camera_joint" type="fixed">
    <origin rpy="0 0 0" xyz="0.45 0.0 .1"/>
    <parent link="base_link"/>
    <child link="camera_link"/>
  </joint>
  <link name="camera_link">
    <inertial>
      <mass value="0.200"/>
      <origin rpy="0 0 0" xyz="0 0 0"/>
      <inertia ixx="5.8083e-4" ixy="0" ixz="0" iyy="3.0833e-5" iyz="0" izz="5.9083e-4"/>
    </inertial>
    <visual>
      <origin rpy="0 0 0" xyz="0 0 0"/>
      <geometry>
        <mesh filename="package://hector_sensors_description/meshes/asus_camera/asus_camera_simple.dae"/>
      </geometry>
    </visual>
    <!--        
      <collision>
          <origin xyz="0 0 0" rpy="0 0 0" />
          <geometry>
              <box size="0.035 0.185 0.025"/>
          </geometry>
          </collision>
          -->
    <collision>
      <origin rpy="0 0 0" xyz="0 0 0"/>
      <geometry>
        <mesh filename="package://hector_sensors_description/meshes/asus_camera/asus_camera_simple.dae"/>
      </geometry>
    </collision>
  </link>
  <joint name="camera_depth_joint" type="fixed">
    <origin rpy="0 0 0" xyz="0.0 0.049 0.0"/>
    <parent link="camera_link"/>
    <child link="camera_depth_frame"/>
  </joint>
  <link name="camera_depth_frame"/>
  <joint name="camera_depth_optical_joint" type="fixed">
    <origin rpy="-1.57079632679 0.0 -1.57079632679" xyz="0 0 0"/>
    <parent link="camera_depth_frame"/>
    <child link="camera_depth_optical_frame"/>
  </joint>
  <link name="camera_depth_optical_frame"/>
  <joint name="camera_rgb_joint" type="fixed">
    <origin rpy="0 0 0" xyz="0.0 0.022 0.0"/>
    <parent link="camera_link"/>
    <child link="camera_rgb_frame"/>
  </joint>
  <link name="camera_rgb_frame"/>
  <joint name="camera_rgb_optical_joint" type="fixed">
    <origin rpy="-1.57079632679 0.0 -1.57079632679" xyz="0 0 0"/>
    <parent link="camera_rgb_frame"/>
    <child link="camera_rgb_optical_frame"/>
  </joint>
  <link name="camera_rgb_optical_frame"/>
  <!-- ASUS Xtion PRO camera for simulation -->
  <gazebo reference="camera_depth_frame">
    <sensor name="camera" type="depth">
      <update_rate>20</update_rate>
      <camera>
        <horizontal_fov>1.09606677025</horizontal_fov>
        <image>
          <format>R8G8B8</format>
          <width>640</width>
          <height>480</height>
        </image>
        <clip>
          <near>0.5</near>
          <far>9</far>
        </clip>
      </camera>
      <plugin filename="libgazebo_ros_openni_kinect.so" name="camera_camera_controller">
        <imageTopicName>camera/rgb/image_raw</imageTopicName>
        <cameraInfoTopicName>camera/rgb/camera_info</cameraInfoTopicName>
        <depthImageTopicName>camera/depth/image_raw</depthImageTopicName>
        <depthImageCameraInfoTopicName>camera/depth/camera_info</depthImageCameraInfoTopicName>
        <pointCloudTopicName>camera/depth/points</pointCloudTopicName>
        <frameName>camera_depth_optical_frame</frameName>
      </plugin>
    </sensor>
  </gazebo>
  <gazebo>
    <plugin filename="libhector_gazebo_ros_imu.so" name="imu_controller">
      <updateRate>50.0</updateRate>
      <bodyName>imu_link</bodyName>
      <topicName>imu/data</topicName>
      <accelDrift>0.005 0.005 0.005</accelDrift>
      <accelGaussianNoise>0.005 0.005 0.005</accelGaussianNoise>
      <rateDrift>0.005 0.005 0.005 </rateDrift>
      <rateGaussianNoise>0.005 0.005 0.005 </rateGaussianNoise>
      <headingDrift>0.005</headingDrift>
      <headingGaussianNoise>0.005</headingGaussianNoise>
    </plugin>
  </gazebo>
  <link name="imu_link">
    <inertial>
      <mass value="0.001"/>
      <origin rpy="0 0 0" xyz="0 0 0"/>
      <inertia ixx="1e-09" ixy="0.0" ixz="0.0" iyy="1e-09" iyz="0.0" izz="1e-09"/>
    </inertial>
  </link>
  <joint name="imu_joint" type="fixed">
    <parent link="base_link"/>
    <child link="imu_link"/>
  </joint>
  <gazebo>
    <plugin filename="libgazebo_ros_p3d.so" name="p3d_base_controller">
      <alwaysOn>true</alwaysOn>
      <updateRate>10.0</updateRate>
      <bodyName>base_link</bodyName>
      <topicName>odom/ground_truth</topicName>
      <gaussianNoise>0.01</gaussianNoise>
      <frameName>world</frameName>
      <xyzOffsets>0 0 0</xyzOffsets>
      <rpyOffsets>0 0 0</rpyOffsets>
    </plugin>
  </gazebo>
</robot>
